Workbook

Sheet MAIN
A1: Link | B1: Order Name | C1: Email | D1: Phone | E1: Shipping Name | F1: Address | G1: City | H1: State/Province | I1: Zip/Postal Code | J1: Country | K1: Product Name | L1: Product SKU | M1: Product Price | N1: Delivery Location | O1: Room Number | P1: Delivery Date | Q1: Delivery Time | R1: Non-University Housing Address | S1: Location Type | T1: Delivery Location 2 | U1: Building | V1: Room Number 2 | W1: Address 2 | X1: Delivery Date 2 | Y1: Delivery Time 2 | Z1: Insurance | AA1: Non-University Housing Address 2 | AB1: Location Type 2 | AC1: Ship From Address | AD1: Pickup Address | AE1: Pickup Date | AF1: Pickup Time | AG1: Pickup Location | AH1: Ship To Address | AI1: Notes | AJ1: Student Name | AK1: Customer Name | AL1: Kit delivery status | AM1: Student/Customer Phone number NEW
A2: =HYPERLINK("https://utrucking.myshopify.com/admin/orders?query="&RIGHT(B2,LEN(B2)-1)) -> https://utrucking.myshopify.com/admin/orders?query=13851 | B2: #13851 | C2: a.dalen@wustl.edu | D2: 5402078205 | E2: Dalen Ainsworth | K2: Summer Storage | L2: 1 [Included with Registration] | O2: 3091 | P2: 45877 | Q2: 09:00 AM to 11:00 AM | U2: Eliot A | V2: 3091 | X2: 45877 | Y2: 09:00 AM to 11:00 AM | Z2: Included Insurance | AL2: {=IFERROR(IFS(XLOOKUP(B2, 'Kit Delivery Status'!$U:$U, 'Kit Delivery Status'!$K:$K) = "Complete", "DELIVERED", XLOOKUP(B2, 'Kit Delivery Status'!$U:$U, 'Kit Delivery Status'!$K:$K) = "Issue", "ISSUE"), "")}
A3: =HYPERLINK("https://utrucking.myshopify.com/admin/orders?query="&RIGHT(B3,LEN(B3)-1)) -> https://utrucking.myshopify.com/admin/orders?query=14045 | B3: #14045 | C3: helenmives@gmail.com | D3: 857-218-8168 | E3: Helen Ives | K3: Storage Item Return | N3: University Housing | O3: Apartment 324-B | P3: 45890 | Q3: 09:00 AM - 11:00 AM | U3: Greenway Apartments | V3: Apartment 324-B | X3: 45890 | Y3: 09:00 AM - 11:00 AM | AI3: The address on my boxes is no longer accurate, and the address I have put here (for WashU housing) is the one that should be used for all of my boxes. Many thanks! | AL3: {=IFERROR(IFS(XLOOKUP(B3, 'Kit Delivery Status'!$U:$U, 'Kit Delivery Status'!$K:$K) = "Complete", "DELIVERED", XLOOKUP(B3, 'Kit Delivery Status'!$U:$U, 'Kit Delivery Status'!$K:$K) = "Issue", "ISSUE"), "")}
A4: =HYPERLINK("https://utrucking.myshopify.com/admin/orders?query="&RIGHT(B4,LEN(B4)-1)) -> https://utrucking.myshopify.com/admin/orders?query=14075 | B4: #14075 | C4: cclee@wustl.edu | D4: 9495312000 | E4: Chelsea Lee | K4: Storage Item Return | N4: University Housing | O4: 4052 | P4: 45891 | Q4: 03:00 PM - 05:00 PM | U4: Nemerov | V4: 4052 | X4: 45891 | Y4: 03:00 PM - 05:00 PM | AI4: It would be appreciated if my stuff can be delivered to my room, but if not possible, leaving it in the common room of 4050 is good as well. | AL4: {=IFERROR(IFS(XLOOKUP(B4, 'Kit Delivery Status'!$U:$U, 'Kit Delivery Status'!$K:$K) = "Complete", "DELIVERED", XLOOKUP(B4, 'Kit Delivery Status'!$U:$U, 'Kit Delivery Status'!$K:$K) = "Issue", "ISSUE"), "")}
A5: =HYPERLINK("https://utrucking.myshopify.com/admin/orders?query="&RIGHT(B5,LEN(B5)-1)) -> https://utrucking.myshopify.com/admin/orders?query=14116 | B5: #14116 | C5: benschwed9876@wustl.edu | D5: 5169985553 | E5: Benjamin Schwed | K5: Appliance Rental | L5: Standard Mini Fridge + Microwave | N5: University Housing | O5: 3304 | P5: 45883 | Q5: 09:00 AM - 11:00 AM | U5: Danforth | V5: 3304 | X5: 45883 | Y5: 09:00 AM - 11:00 AM | AI5: delivery-08/13/2025 pick up-05/06/2026 | AL5: {=IFERROR(IFS(XLOOKUP(B5, 'Kit Delivery Status'!$U:$U, 'Kit Delivery Status'!$K:$K) = "Complete", "DELIVERED", XLOOKUP(B5, 'Kit Delivery Status'!$U:$U, 'Kit Delivery Status'!$K:$K) = "Issue", "ISSUE"), "")}
A6: https://admin.shopify.com/store/utrucking/orders/5794999468220?link_source=search | B6: #14171 | C6: Marlowe@wustl.edu | D6: 914-646-4187 | E6: Taylor Marlowe | K6: Tri-State Area Home Pickups | L6: $100 per item [Included] | N6: University Housing | O6: 3331 | P6: 45877 | Q6: 09:00 AM - 11:00 AM | U6: Lien | V6: 3331 | X6: 45877 | Y6: 09:00 AM - 11:00 AM | AL6: {=IFERROR(IFS(XLOOKUP(B6, 'Kit Delivery Status'!$U:$U, 'Kit Delivery Status'!$K:$K) = "Complete", "DELIVERED", XLOOKUP(B6, 'Kit Delivery Status'!$U:$U, 'Kit Delivery Status'!$K:$K) = "Issue", "ISSUE"), "")}
A7: =HYPERLINK("https://utrucking.myshopify.com/admin/orders?query="&RIGHT(B7,LEN(B7)-1)) -> https://utrucking.myshopify.com/admin/orders?query=14191 | B7: #14191 | C7: jessicajlee@wustl.edu | D7: 7087372613 | E7: Jessica Lee | K7: Storage Item Return | N7: University Housing | O7: 4000 | P7: 45876 | Q7: 09:00 AM - 11:00 AM | U7: Nemerov | V7: 4000 | X7: 45876 | Y7: 09:00 AM - 11:00 AM | AL7: {=IFERROR(IFS(XLOOKUP(B7, 'Kit Delivery Status'!$U:$U, 'Kit Delivery Status'!$K:$K) = "Complete", "DELIVERED", XLOOKUP(B7, 'Kit Delivery Status'!$U:$U, 'Kit Delivery Status'!$K:$K) = "Issue", "ISSUE"), "")}
A8: =HYPERLINK("https://utrucking.myshopify.com/admin/orders?query="&RIGHT(B8,LEN(B8)-1)) -> https://utrucking.myshopify.com/admin/orders?query=14194 | B8: #14194 | C8: cindyhellman1204@gmail.com | D8: (516) 508-8030 | E8: cindy hellman | F8: the everly 6105 delmar blvd st louis mo 63112 apt 1321 | K8: Apartment Moves | L8: 1 [Included with Registration] | P8: 45857 | Q8: 10:00 AM - 12:00 PM | X8: 45857 | Y8: 10:00 AM - 12:00 PM | AC8: the everly 6105 delmar blvd st louis mo 63112 apt 1321 | AE8: 45857 | AI8: moving to citizens park 4643 lindell blvd st louis mo 63108 apt 1110 *** CAN YOU PLEASE DROP OFF the BOXES ON MONDAY APRIL 28th *** contact phone 516-508-8030 MARISA BENJAMIN**** | AL8: {=IFERROR(IFS(XLOOKUP(B8, 'Kit Delivery Status'!$U:$U, 'Kit Delivery Status'!$K:$K) = "Complete", "DELIVERED", XLOOKUP(B8, 'Kit Delivery Status'!$U:$U, 'Kit Delivery Status'!$K:$K) = "Issue", "ISSUE"), "")}
A9: =HYPERLINK("https://utrucking.myshopify.com/admin/orders?query="&RIGHT(B9,LEN(B9)-1)) -> https://utrucking.myshopify.com/admin/orders?query=13918 | B9: #13918 | C9: garelick@wustl.edu | D9: (201) 400-7616 | E9: Jared Garelick | F9: 407 Thornden Street | K9: Nationwide Ship to School | P9: 45889 | Q9: 12:00 PM - 02:00 PM | X9: 45889 | Y9: 12:00 PM - 02:00 PM | AE9: 45889 | AL9: {=IFERROR(IFS(XLOOKUP(B9, 'Kit Delivery Status'!$U:$U, 'Kit Delivery Status'!$K:$K) = "Complete", "DELIVERED", XLOOKUP(B9, 'Kit Delivery Status'!$U:$U, 'Kit Delivery Status'!$K:$K) = "Issue", "ISSUE"), "")}
A10: =HYPERLINK("https://utrucking.myshopify.com/admin/orders?query="&RIGHT(B10,LEN(B10)-1)) -> https://utrucking.myshopify.com/admin/orders?query=14224 | B10: #14224 | C10: m.bell@wustl.edu | D10: (312) 344-0050 | E10: Chanel Bell | F10: 705 McCardle Drive | K10: Nationwide Ship to School | N10: University Housing | P10: 45870 | Q10: 09:00 AM - 11:00 AM | U10: DON'T KNOW YET (put 'XXX' for room #) | V10: XXX | X10: 45870 | Y10: 09:00 AM - 11:00 AM | AE10: 45870 | AL10: {=IFERROR(IFS(XLOOKUP(B10, 'Kit Delivery Status'!$U:$U, 'Kit Delivery Status'!$K:$K) = "Complete", "DELIVERED", XLOOKUP(B10, 'Kit Delivery Status'!$U:$U, 'Kit Delivery Status'!$K:$K) = "Issue", "ISSUE"), "")}
A11: =HYPERLINK("https://utrucking.myshopify.com/admin/orders?query="&RIGHT(B11,LEN(B11)-1)) -> https://utrucking.myshopify.com/admin/orders?query=14409 | B11: #14409 | C11: m.b.szwartz@wustl.edu | D11: (1215) 432-7954 | E11: Lynda Szwartz | F11: 605 Zollinger Way | K11: Nationwide Ship to School | N11: University Housing | P11: 45884 | Q11: 09:00 AM to 11:00 AM | U11: Umrath | V11: 3301 | X11: 45884 | Y11: 09:00 AM to 11:00 AM | AE11: 45884 | AL11: {=IFERROR(IFS(XLOOKUP(B11, 'Kit Delivery Status'!$U:$U, 'Kit Delivery Status'!$K:$K) = "Complete", "DELIVERED", XLOOKUP(B11, 'Kit Delivery Status'!$U:$U, 'Kit Delivery Status'!$K:$K) = "Issue", "ISSUE"), "")}
A12: =HYPERLINK("https://utrucking.myshopify.com/admin/orders?query="&RIGHT(B12,LEN(B12)-1)) -> https://utrucking.myshopify.com/admin/orders?query=14473 | B12: #14473 | C12: j.jaffe@wustl.edu | D12: (315) 382-7241 | E12: Jonah Jaffe | F12: 4852 Carey Drive | K12: Nationwide Ship to School | N12: University Housing | P12: 45883 | Q12: 10:00 AM - 12:00 PM | U12: Koenig | V12: 2212 | X12: 45883 | Y12: 10:00 AM - 12:00 PM | AE12: 45883 | AL12: {=IFERROR(IFS(XLOOKUP(B12, 'Kit Delivery Status'!$U:$U, 'Kit Delivery Status'!$K:$K) = "Complete", "DELIVERED", XLOOKUP(B12, 'Kit Delivery Status'!$U:$U, 'Kit Delivery Status'!$K:$K) = "Issue", "ISSUE"), "")}
A13: https://admin.shopify.com/store/utrucking/orders/5811833962684?link_source=search | B13: #14478 | C13: hermione@wustl.edu | D13: 314-745-7657 | E13: Yutong Xie | F13: 6515 Wydown Boulevard | K13: Storage Item Return | N13: Non-University Housing | P13: 45893 | Q13: 02:00 PM - 04:00 PM | R13: 6105 Delmar BIvd. Apt 515 | X13: 45893 | Y13: 02:00 PM - 04:00 PM | AE13: 45893 | AL13: {=IFERROR(IFS(XLOOKUP(B13, 'Kit Delivery Status'!$U:$U, 'Kit Delivery Status'!$K:$K) = "Complete", "DELIVERED", XLOOKUP(B13, 'Kit Delivery Status'!$U:$U, 'Kit Delivery Status'!$K:$K) = "Issue", "ISSUE"), "")}
A14: =HYPERLINK("https://utrucking.myshopify.com/admin/orders?query="&RIGHT(B14,LEN(B14)-1)) -> https://utrucking.myshopify.com/admin/orders?query=14528 | B14: #14528 | C14: qiumin@wustl.edu | D14: (571) 275-5119 | E14: Michelle Zhang | F14: 1200 N Quaker Ln | K14: Nationwide Ship to School | N14: University Housing | P14: 45883 | Q14: 03:00 PM - 05:00 PM | U14: Lee | V14: 313 | X14: 45883 | Y14: 03:00 PM - 05:00 PM | AE14: 45883 | AL14: {=IFERROR(IFS(XLOOKUP(B14, 'Kit Delivery Status'!$U:$U, 'Kit Delivery Status'!$K:$K) = "Complete", "DELIVERED", XLOOKUP(B14, 'Kit Delivery Status'!$U:$U, 'Kit Delivery Status'!$K:$K) = "Issue", "ISSUE"), "")}
A15: =HYPERLINK("https://utrucking.myshopify.com/admin/orders?query="&RIGHT(B15,LEN(B15)-1)) -> https://utrucking.myshopify.com/admin/orders?query=14587 | B15: #14587 | C15: allen.r.g@wustl.edu | D15: (713) 898-3521 | E15: Ryan Allen | F15: 3614 Durness Way | K15: Nationwide Ship to School | N15: University Housing | P15: 45784 | Q15: 02:00 PM - 04:00 PM | U15: Umrath | V15: 2237 | X15: 45784 | Y15: 02:00 PM - 04:00 PM | AE15: 45784 | AL15: {=IFERROR(IFS(XLOOKUP(B15, 'Kit Delivery Status'!$U:$U, 'Kit Delivery Status'!$K:$K) = "Complete", "DELIVERED", XLOOKUP(B15, 'Kit Delivery Status'!$U:$U, 'Kit Delivery Status'!$K:$K) = "Issue", "ISSUE"), "")}
A16: =HYPERLINK("https://utrucking.myshopify.com/admin/orders?query="&RIGHT(B16,LEN(B16)-1)) -> https://utrucking.myshopify.com/admin/orders?query=14755 | B16: #14755 | C16: c.a.warren@wustl.edu | D16: (713) 206-1500 | E16: Morgan Warren | F16: 6711 Stella Link Road | K16: Nationwide Ship to School | N16: University Housing | P16: 45883 | Q16: 9:00 AM - 11:00 AM | U16: Dauten | V16: 432 | X16: 45883 | Y16: 9:00 AM - 11:00 AM | AE16: 45883 | AL16: {=IFERROR(IFS(XLOOKUP(B16, 'Kit Delivery Status'!$U:$U, 'Kit Delivery Status'!$K:$K) = "Complete", "DELIVERED", XLOOKUP(B16, 'Kit Delivery Status'!$U:$U, 'Kit Delivery Status'!$K:$K) = "Issue", "ISSUE"), "")}
A17: =HYPERLINK("https://utrucking.myshopify.com/admin/orders?query="&RIGHT(B17,LEN(B17)-1)) -> https://utrucking.myshopify.com/admin/orders?query=14825 | B17: #14825 | C17: b.welford@wustl.edu | D17: (1949) 500-1022 | E17: Benjamin Welford | F17: 39 Blue Heron | K17: Nationwide Ship to School | N17: University Housing | P17: 45883 | Q17: 09:00 AM - 11:00 AM | U17: Park | V17: 280 | X17: 45883 | Y17: 09:00 AM - 11:00 AM | AE17: 45883 | AL17: {=IFERROR(IFS(XLOOKUP(B17, 'Kit Delivery Status'!$U:$U, 'Kit Delivery Status'!$K:$K) = "Complete", "DELIVERED", XLOOKUP(B17, 'Kit Delivery Status'!$U:$U, 'Kit Delivery Status'!$K:$K) = "Issue", "ISSUE"), "")}
A18: =HYPERLINK("https://utrucking.myshopify.com/admin/orders?query="&RIGHT(B18,LEN(B18)-1)) -> https://utrucking.myshopify.com/admin/orders?query=14979 | B18: #14979 | C18: joyce.zhao@wustl.edu | D18: (840) 205-6469 | E18: Joyce Zhao | F18: 1175 W Baseline Rd | K18: Nationwide Ship to School | N18: University Housing | P18: 45883 | Q18: 11:00 AM - 01:00 PM | U18: Shanedling | V18: 333 | X18: 45883 | Y18: 11:00 AM - 01:00 PM | AE18: 45883 | AL18: {=IFERROR(IFS(XLOOKUP(B18, 'Kit Delivery Status'!$U:$U, 'Kit Delivery Status'!$K:$K) = "Complete", "DELIVERED", XLOOKUP(B18, 'Kit Delivery Status'!$U:$U, 'Kit Delivery Status'!$K:$K) = "Issue", "ISSUE"), "")}
A19: =HYPERLINK("https://utrucking.myshopify.com/admin/orders?query="&RIGHT(B19,LEN(B19)-1)) -> https://utrucking.myshopify.com/admin/orders?query=14984 | B19: #14984 | C19: samanthar@wustl.edu | D19: (312) 351-0710 | E19: Samantha Rosenberg | F19: 256 Moraine Road | K19: Nationwide Ship to School | N19: University Housing | P19: 45883 | Q19: 09:00 AM - 11:00 AM | U19: Danforth | V19: 3321 | X19: 45883 | Y19: 09:00 AM - 11:00 AM | AE19: 45883 | AL19: {=IFERROR(IFS(XLOOKUP(B19, 'Kit Delivery Status'!$U:$U, 'Kit Delivery Status'!$K:$K) = "Complete", "DELIVERED", XLOOKUP(B19, 'Kit Delivery Status'!$U:$U, 'Kit Delivery Status'!$K:$K) = "Issue", "ISSUE"), "")}
A20: =HYPERLINK("https://utrucking.myshopify.com/admin/orders?query="&RIGHT(B20,LEN(B20)-1)) -> https://utrucking.myshopify.com/admin/orders?query=14988 | B20: #14988 | C20: eruth@wustl.edu | D20: (917) 767-3188 | E20: Lexie Ruth | F20: 3212 Gulfstream Road | K20: Nationwide Ship to School | N20: University Housing | P20: 45881 | Q20: 09:00 AM - 11:00 AM | U20: Lien | V20: 1117 | X20: 45881 | Y20: 09:00 AM - 11:00 AM | AE20: 45881 | AL20: {=IFERROR(IFS(XLOOKUP(B20, 'Kit Delivery Status'!$U:$U, 'Kit Delivery Status'!$K:$K) = "Complete", "DELIVERED", XLOOKUP(B20, 'Kit Delivery Status'!$U:$U, 'Kit Delivery Status'!$K:$K) = "Issue", "ISSUE"), "")}
A21: =HYPERLINK("https://utrucking.myshopify.com/admin/orders?query="&RIGHT(B21,LEN(B21)-1)) -> https://utrucking.myshopify.com/admin/orders?query=14989 | B21: #14989 | C21: h.thun@wustl.edu | E21: Jola Thun | F21: 500 El Medio Avenue | K21: Nationwide Ship to School | N21: University Housing | P21: 45805 | Q21: 09:00 AM - 11:00 AM | U21: Mudd | V21: 271 | X21: 45805 | Y21: 09:00 AM - 11:00 AM | AE21: 45805 | AL21: {=IFERROR(IFS(XLOOKUP(B21, 'Kit Delivery Status'!$U:$U, 'Kit Delivery Status'!$K:$K) = "Complete", "DELIVERED", XLOOKUP(B21, 'Kit Delivery Status'!$U:$U, 'Kit Delivery Status'!$K:$K) = "Issue", "ISSUE"), "")}
A22: =HYPERLINK("https://utrucking.myshopify.com/admin/orders?query="&RIGHT(B22,LEN(B22)-1)) -> https://utrucking.myshopify.com/admin/orders?query=14994 | B22: #14994 | C22: b.k.wagner@wustl.edu | D22: (678) 830-6322 | E22: Blair (Student) Wagner | F22: 7242 Sweetwater Valley | K22: Nationwide Ship to School | N22: University Housing | P22: 45870 | Q22: 09:00 AM - 11:00 AM | U22: Dardick | V22: 1109-a | X22: 45870 | Y22: 09:00 AM - 11:00 AM | AE22: 45870 | AL22: {=IFERROR(IFS(XLOOKUP(B22, 'Kit Delivery Status'!$U:$U, 'Kit Delivery Status'!$K:$K) = "Complete", "DELIVERED", XLOOKUP(B22, 'Kit Delivery Status'!$U:$U, 'Kit Delivery Status'!$K:$K) = "Issue", "ISSUE"), "")}
A23: https://admin.shopify.com/store/utrucking/orders/5837335822524?link_source=search | B23: #14996 | C23: a.dalen@wustl.edu | D23: 540-207-8205 | E23: Dalen Ainsworth | F23: 9700 Renfield Ct | K23: Appliance Rental | L23: Double Door mini fridge | M23: 145 | N23: University Housing | O23: 3301 | P23: 45792 | Q23: 09:00 AM - 11:00 AM | U23: Koenig | V23: 3301 | X23: 45792 | Y23: 09:00 AM - 11:00 AM | AL23: {=IFERROR(IFS(XLOOKUP(B23, 'Kit Delivery Status'!$U:$U, 'Kit Delivery Status'!$K:$K) = "Complete", "DELIVERED", XLOOKUP(B23, 'Kit Delivery Status'!$U:$U, 'Kit Delivery Status'!$K:$K) = "Issue", "ISSUE"), "")}
A24: =HYPERLINK("https://utrucking.myshopify.com/admin/orders?query="&RIGHT(B24,LEN(B24)-1)) -> https://utrucking.myshopify.com/admin/orders?query=15020 | B24: #15020 | C24: m.k.tan@wustl.edu | D24: (310) 808-3281 | E24: Marisa Tan | F24: 18 Misty Acres Rd | K24: Nationwide Ship to School | N24: University Housing | P24: 45883 | Q24: 09:00 AM to 11:00 AM | U24: Dardick | V24: 2208 | X24: 45883 | Y24: 09:00 AM to 11:00 AM | AE24: 45883 | AL24: {=IFERROR(IFS(XLOOKUP(B24, 'Kit Delivery Status'!$U:$U, 'Kit Delivery Status'!$K:$K) = "Complete", "DELIVERED", XLOOKUP(B24, 'Kit Delivery Status'!$U:$U, 'Kit Delivery Status'!$K:$K) = "Issue", "ISSUE"), "")}
A25: =HYPERLINK("https://utrucking.myshopify.com/admin/orders?query="&RIGHT(B25,LEN(B25)-1)) -> https://utrucking.myshopify.com/admin/orders?query=15032 | B25: #15032 | C25: j.t.lee@wustl.edu | D25: (415) 770-3664 | E25: Jacob Lee | F25: 630 11th Avenue | K25: Nationwide Ship to School | N25: University Housing | P25: 45883 | Q25: 09:00 AM - 11:00 AM | U25: Koenig | V25: 4407 | X25: 45883 | Y25: 09:00 AM - 11:00 AM | AE25: 45883 | AL25: {=IFERROR(IFS(XLOOKUP(B25, 'Kit Delivery Status'!$U:$U, 'Kit Delivery Status'!$K:$K) = "Complete", "DELIVERED", XLOOKUP(B25, 'Kit Delivery Status'!$U:$U, 'Kit Delivery Status'!$K:$K) = "Issue", "ISSUE"), "")}
A26: =HYPERLINK("https://utrucking.myshopify.com/admin/orders?query="&RIGHT(B26,LEN(B26)-1)) -> https://utrucking.myshopify.com/admin/orders?query=15036 | B26: #15036 | C26: a.covello@wustl.edu | D26: (973) 440-7049 | E26: Andrew Covello | F26: 7 Loantaka Lane N | K26: Nationwide Ship to School | N26: University Housing | P26: 45881 | Q26: 09:00 AM - 11:00 AM | U26: DON'T KNOW YET (put 'XXX' for room #) | V26: XXX | X26: 45881 | Y26: 09:00 AM - 11:00 AM | AE26: 45881 | AL26: {=IFERROR(IFS(XLOOKUP(B26, 'Kit Delivery Status'!$U:$U, 'Kit Delivery Status'!$K:$K) = "Complete", "DELIVERED", XLOOKUP(B26, 'Kit Delivery Status'!$U:$U, 'Kit Delivery Status'!$K:$K) = "Issue", "ISSUE"), "")}
A27: =HYPERLINK("https://utrucking.myshopify.com/admin/orders?query="&RIGHT(B27,LEN(B27)-1)) -> https://utrucking.myshopify.com/admin/orders?query=15039 | B27: #15039 | C27: a.plaxe@wustl.edu | D27: (917) 455-1134 | E27: Amanda Plaxe | F27: 214 West 85th St | K27: Nationwide Ship to School | N27: University Housing | P27: 45889 | Q27: 09:00 AM - 11:00 AM | U27: Eliot B | V27: 2103 | X27: 45889 | Y27: 09:00 AM - 11:00 AM | AE27: 45889 | AL27: {=IFERROR(IFS(XLOOKUP(B27, 'Kit Delivery Status'!$U:$U, 'Kit Delivery Status'!$K:$K) = "Complete", "DELIVERED", XLOOKUP(B27, 'Kit Delivery Status'!$U:$U, 'Kit Delivery Status'!$K:$K) = "Issue", "ISSUE"), "")}
A28: =HYPERLINK("https://utrucking.myshopify.com/admin/orders?query="&RIGHT(B28,LEN(B28)-1)) -> https://utrucking.myshopify.com/admin/orders?query=15055 | B28: #15055 | C28: anna.j.schwartz@wustl.edu | D28: (404) 345-7378 | E28: Anna Schwartz | F28: 4416 Saint Andrews Drive Northwest | K28: Nationwide Ship to School | N28: University Housing | P28: 45878 | Q28: 09:00 AM to 11:00 AM | U28: Village House | V28: 4071-a | X28: 45878 | Y28: 09:00 AM to 11:00 AM | AE28: 45878 | AL28: {=IFERROR(IFS(XLOOKUP(B28, 'Kit Delivery Status'!$U:$U, 'Kit Delivery Status'!$K:$K) = "Complete", "DELIVERED", XLOOKUP(B28, 'Kit Delivery Status'!$U:$U, 'Kit Delivery Status'!$K:$K) = "Issue", "ISSUE"), "")}
A29: =HYPERLINK("https://utrucking.myshopify.com/admin/orders?query="&RIGHT(B29,LEN(B29)-1)) -> https://utrucking.myshopify.com/admin/orders?query=15080 | B29: #15080 | C29: megcheung2016@gmail.com | D29: (914) 255-7538 | E29: Sohta Cheung-Naito | F29: 175 Underhill Rd | K29: Nationwide Ship to School | N29: University Housing | P29: 45883 | Q29: 10:00 AM - 12:00 PM | U29: Koenig | V29: 1117 | X29: 45883 | Y29: 10:00 AM - 12:00 PM | AE29: 45883 | AL29: {=IFERROR(IFS(XLOOKUP(B29, 'Kit Delivery Status'!$U:$U, 'Kit Delivery Status'!$K:$K) = "Complete", "DELIVERED", XLOOKUP(B29, 'Kit Delivery Status'!$U:$U, 'Kit Delivery Status'!$K:$K) = "Issue", "ISSUE"), "")}
A30: =HYPERLINK("https://utrucking.myshopify.com/admin/orders?query="&RIGHT(B30,LEN(B30)-1)) -> https://utrucking.myshopify.com/admin/orders?query=15081 | B30: #15081 | C30: 0 | D30: (1214) 336-9342 | E30: julie liberman | F30: 2404 WING POINT LN | K30: Nationwide Ship to School | N30: University Housing | P30: 45883 | Q30: 09:00 AM - 11:00 AM | U30: Umrath | V30: 3322 | X30: 45883 | Y30: 09:00 AM - 11:00 AM | AE30: 45883 | AL30: {=IFERROR(IFS(XLOOKUP(B30, 'Kit Delivery Status'!$U:$U, 'Kit Delivery Status'!$K:$K) = "Complete", "DELIVERED", XLOOKUP(B30, 'Kit Delivery Status'!$U:$U, 'Kit Delivery Status'!$K:$K) = "Issue", "ISSUE"), "")}
A31: =HYPERLINK("https://utrucking.myshopify.com/admin/orders?query="&RIGHT(B31,LEN(B31)-1)) -> https://utrucking.myshopify.com/admin/orders?query=15082 | B31: #15082 | C31: edwardcartonz@gmail.com | D31: (805) 637-5739 | E31: Maohua Zhang | F31: 775 Camino Del Sur | K31: Nationwide Ship to School | N31: Non-University Housing | P31: 45822 | Q31: 01:00 PM - 03:00 PM | X31: 45822 | Y31: 01:00 PM - 03:00 PM | AE31: 45822 | AL31: {=IFERROR(IFS(XLOOKUP(B31, 'Kit Delivery Status'!$U:$U, 'Kit Delivery Status'!$K:$K) = "Complete", "DELIVERED", XLOOKUP(B31, 'Kit Delivery Status'!$U:$U, 'Kit Delivery Status'!$K:$K) = "Issue", "ISSUE"), "")}
A32: =HYPERLINK("https://utrucking.myshopify.com/admin/orders?query="&RIGHT(B32,LEN(B32)-1)) -> https://utrucking.myshopify.com/admin/orders?query=15103 | B32: #15103 | C32: faier@wustl.edu | D32: (224) 578-2645 | E32: Sharon Faier | F32: 8182 South Saint Paul Way | K32: Nationwide Ship to School | N32: University Housing | P32: 45883 | Q32: 09:00 AM - 11:00 AM | U32: Myers | V32: 413 | X32: 45883 | Y32: 09:00 AM - 11:00 AM | AE32: 45883 | AL32: {=IFERROR(IFS(XLOOKUP(B32, 'Kit Delivery Status'!$U:$U, 'Kit Delivery Status'!$K:$K) = "Complete", "DELIVERED", XLOOKUP(B32, 'Kit Delivery Status'!$U:$U, 'Kit Delivery Status'!$K:$K) = "Issue", "ISSUE"), "")}
A33: =HYPERLINK("https://utrucking.myshopify.com/admin/orders?query="&RIGHT(B33,LEN(B33)-1)) -> https://utrucking.myshopify.com/admin/orders?query=15104 | B33: #15104 | C33: l.d.young@wustl.edu | D33: (949) 254-8160 | E33: Sandra Young | F33: 72 Cunningham | K33: Nationwide Ship to School | N33: University Housing | P33: 45883 | Q33: 09:00 AM - 11:00 AM | U33: Koenig | V33: I don't know yet | X33: 45883 | Y33: 09:00 AM - 11:00 AM | AE33: 45883 | AL33: {=IFERROR(IFS(XLOOKUP(B33, 'Kit Delivery Status'!$U:$U, 'Kit Delivery Status'!$K:$K) = "Complete", "DELIVERED", XLOOKUP(B33, 'Kit Delivery Status'!$U:$U, 'Kit Delivery Status'!$K:$K) = "Issue", "ISSUE"), "")}
A34: =HYPERLINK("https://utrucking.myshopify.com/admin/orders?query="&RIGHT(B34,LEN(B34)-1)) -> https://utrucking.myshopify.com/admin/orders?query=15128 | B34: #15128 | C34: bosques@wustl.edu | D34: (617) 999-8561 | E34: Gustavo Bosques | F34: 198 Overlook Rd | K34: Nationwide Ship to School | N34: University Housing | P34: 45882 | Q34: 03:00 PM - 05:00 PM | U34: DON'T KNOW YET (put 'XXX' for room #) | V34: xxx | X34: 45882 | Y34: 03:00 PM - 05:00 PM | AE34: 45882 | AL34: {=IFERROR(IFS(XLOOKUP(B34, 'Kit Delivery Status'!$U:$U, 'Kit Delivery Status'!$K:$K) = "Complete", "DELIVERED", XLOOKUP(B34, 'Kit Delivery Status'!$U:$U, 'Kit Delivery Status'!$K:$K) = "Issue", "ISSUE"), "")}
A35: =HYPERLINK("https://utrucking.myshopify.com/admin/orders?query="&RIGHT(B35,LEN(B35)-1)) -> https://utrucking.myshopify.com/admin/orders?query=15129 | B35: #15129 | C35: dina.bean@verizon.net | D35: (1917) 821-5981 | E35: Dina Bean | F35: 8 East 83rd Street | K35: Nationwide Ship to School | N35: University Housing | P35: 45882 | Q35: 10:00 AM - 12:00 PM | U35: Dardick | V35: 2210 | X35: 45882 | Y35: 10:00 AM - 12:00 PM | AE35: 45882 | AL35: {=IFERROR(IFS(XLOOKUP(B35, 'Kit Delivery Status'!$U:$U, 'Kit Delivery Status'!$K:$K) = "Complete", "DELIVERED", XLOOKUP(B35, 'Kit Delivery Status'!$U:$U, 'Kit Delivery Status'!$K:$K) = "Issue", "ISSUE"), "")}
A36: =HYPERLINK("https://utrucking.myshopify.com/admin/orders?query="&RIGHT(B36,LEN(B36)-1)) -> https://utrucking.myshopify.com/admin/orders?query=15134 | B36: #15134 | C36: r.l.shames@wustl.edu | D36: (1917) 603-4125 | E36: Rachel Shames | F36: 500 W End Ave | K36: Nationwide Ship to School | N36: University Housing | P36: 45882 | Q36: 11:00 AM - 01:00 PM | U36: Dardick | V36: 4402 | X36: 45882 | Y36: 11:00 AM - 01:00 PM | AE36: 45882 | AL36: {=IFERROR(IFS(XLOOKUP(B36, 'Kit Delivery Status'!$U:$U, 'Kit Delivery Status'!$K:$K) = "Complete", "DELIVERED", XLOOKUP(B36, 'Kit Delivery Status'!$U:$U, 'Kit Delivery Status'!$K:$K) = "Issue", "ISSUE"), "")}
A37: =HYPERLINK("https://utrucking.myshopify.com/admin/orders?query="&RIGHT(B37,LEN(B37)-1)) -> https://utrucking.myshopify.com/admin/orders?query=15137 | B37: #15137 | C37: b.cayden@wustl.edu | D37: (973) 715-4139 | E37: Sondra Barrison | F37: 115 Scott Drive | K37: Nationwide Ship to School | N37: University Housing | P37: 45889 | Q37: 12:00 PM - 02:00 PM | U37: 6645 University Drive | V37: 1E-A | X37: 45889 | Y37: 12:00 PM - 02:00 PM | AE37: 45889 | AL37: {=IFERROR(IFS(XLOOKUP(B37, 'Kit Delivery Status'!$U:$U, 'Kit Delivery Status'!$K:$K) = "Complete", "DELIVERED", XLOOKUP(B37, 'Kit Delivery Status'!$U:$U, 'Kit Delivery Status'!$K:$K) = "Issue", "ISSUE"), "")}
A38: =HYPERLINK("https://utrucking.myshopify.com/admin/orders?query="&RIGHT(B38,LEN(B38)-1)) -> https://utrucking.myshopify.com/admin/orders?query=15144 | B38: #15144 | C38: Maryraue@gmail.com | D38: (1703) 307-8619 | E38: Mary Raue | F38: 5810 Beech Ave | K38: Nationwide Ship to School | N38: University Housing | P38: 45881 | Q38: 09:00 AM - 11:00 AM | U38: DON'T KNOW YET (put 'XXX' for room #) | V38: XXX | X38: 45881 | Y38: 09:00 AM - 11:00 AM | AE38: 45881 | AL38: {=IFERROR(IFS(XLOOKUP(B38, 'Kit Delivery Status'!$U:$U, 'Kit Delivery Status'!$K:$K) = "Complete", "DELIVERED", XLOOKUP(B38, 'Kit Delivery Status'!$U:$U, 'Kit Delivery Status'!$K:$K) = "Issue", "ISSUE"), "")}
A39: =HYPERLINK("https://utrucking.myshopify.com/admin/orders?query="&RIGHT(B39,LEN(B39)-1)) -> https://utrucking.myshopify.com/admin/orders?query=15148 | B39: #15148 | C39: 0 | D39: (1202) 494-5966 | E39: Hillary Davidson | F39: 9513 Brooke Dr | K39: Nationwide Ship to School | N39: University Housing | O39: 3323 | P39: 45882 | Q39: 11:00 AM - 01:00 PM | U39: Umrath | V39: 3323 | X39: 45882 | Y39: 11:00 AM - 01:00 PM | AE39: 45882 | AL39: {=IFERROR(IFS(XLOOKUP(B39, 'Kit Delivery Status'!$U:$U, 'Kit Delivery Status'!$K:$K) = "Complete", "DELIVERED", XLOOKUP(B39, 'Kit Delivery Status'!$U:$U, 'Kit Delivery Status'!$K:$K) = "Issue", "ISSUE"), "")}
A40: =HYPERLINK("https://utrucking.myshopify.com/admin/orders?query="&RIGHT(B40,LEN(B40)-1)) -> https://utrucking.myshopify.com/admin/orders?query=15150 | B40: #15150 | C40: taliawest7@gmail.com | D40: (458) 256-5639 | E40: Talia West | F40: 4020 94th Ave NE | K40: Nationwide Ship to School | N40: University Housing | P40: 45880 | Q40: 09:00 AM - 11:00 AM | U40: Danforth | V40: 4428 | X40: 45880 | Y40: 09:00 AM - 11:00 AM | AE40: 45880 | AL40: {=IFERROR(IFS(XLOOKUP(B40, 'Kit Delivery Status'!$U:$U, 'Kit Delivery Status'!$K:$K) = "Complete", "DELIVERED", XLOOKUP(B40, 'Kit Delivery Status'!$U:$U, 'Kit Delivery Status'!$K:$K) = "Issue", "ISSUE"), "")}
...

Sheet Filtered MAIN - TEMP
A1: Order URL | B1: Order Name | C1: Email | D1: Phone | E1: Shipping Name | F1: Address | G1: City | H1: State/Province | I1: Zip/Postal Code | J1: Country | K1: Product Name | L1: Product SKU | M1: Product Price | N1: Delivery Location | O1: Room Number | P1: Delivery Date | Q1: Delivery Time | R1: Non-University Housing Address | S1: Location Type | T1: Delivery Location | U1: Building | V1: Room Number | W1: Address | X1: Delivery Date | Y1: Delivery Time | Z1: Insurance | AA1: Non-University Housing Address | AB1: Location Type | AC1: Ship From Address | AD1: Pickup Address | AE1: Pickup Date | AF1: Pickup Time | AG1: Pickup Location | AH1: Ship To Address
A2: https://utrucking.com/admin/orders/5897677144252 | B2: #15216 | C2: emeralda@wustl.edu | E2: Emeralda Jin | F2: 12110 Cameron Drive Duluth United States | G2: Duluth | H2: Georgia | I2: 30097 | J2: United States | K2: Storage Item Return | M2: 1 | N2: University Housing | O2: 141 | P2: 45890 | Q2: 11:00 AM - 01:00 PM | S2: University Housing | T2: University Housing | U2: Mudd | V2: 141 | X2: 45877 | AB2: University Housing
A3: https://utrucking.com/admin/orders/5897705062588 | B3: #15217 | C3: a.hermann@wustl.edu | E3: Andrew Hermann | F3: 1070 Park Avenue Apt. 4B New York United States | G3: New York | H3: New York | I3: 10128-1000 | J3: United States | K3: Tri-State Area Home Pickups | M3: 49 | O3: 2210-A | P3: 45877 | S3: University Housing | T3: University Housing | U3: Dardick | V3: 2210-A | X3: 45877 | Z3: $100 per item [Included] | AB3: University Housing
A4: https://utrucking.com/admin/orders/5897863135420 | B4: #15221 | C4: aiaccino29@yahoo.com | E4: Lauren Iaccino | F4: 6252 Penfield Avenue Woodland Hills United States | G4: Woodland Hills | H4: California | I4: 91367 | J4: United States | K4: Nationwide Ship to School | L4: Nationwide Ship to School | M4: 49 | O4: 312-a | P4: 45877 | S4: University Housing | T4: University Housing | U4: Park | V4: 312-a | X4: 45877 | AB4: University Housing
A5: https://utrucking.com/admin/orders/5898283614396 | B5: #15225 | C5: eiram777@comcast.net | E5: Marie Skwirblies | F5: 428 Fairway Dr Bartlett United States | G5: Bartlett | H5: Illinois | I5: 60103 | J5: United States | K5: Appliance Rental | L5: Double-Door Mini Fridge | M5: 145 | O5: 3134 | P5: 45877 | U5: Village House | V5: 3134 | X5: 45877
A6: https://utrucking.com/admin/orders/5898324410556 | B6: #15226 | C6: g.r.garcia@wustl.edu | E6: Gabriella Garcia | F6: 1426 Canyon Rim Dr NE Albuquerque United States | G6: Albuquerque | H6: New Mexico | I6: 87112 | J6: United States | K6: Nationwide Ship to School | L6: Nationwide Ship to School | M6: 49 | N6: University Housing | O6: 203 | P6: 45883 | Q6: 09:00 AM to 11:00 AM | T6: University Housing | U6: Eliot A | V6: 203 | X6: 45883 | Y6: 09:00 AM to 11:00 AM
A7: https://utrucking.com/admin/orders/5898432577724 | B7: #15227 | C7: ecarrott@hotmail.com | E7: Elizabeth Minnigh | F7: 3854 N Upland St Arlington United States | G7: Arlington | H7: Virginia | I7: 22207 | J7: United States | K7: Nationwide Ship to School | L7: Nationwide Ship to School | M7: 49 | N7: University Housing | O7: 4402 | P7: 45883 | Q7: 09:00 AM to 11:00 AM | T7: University Housing | U7: Danforth | V7: 4402 | X7: 45883 | Y7: 09:00 AM to 11:00 AM
A8: https://utrucking.com/admin/orders/5898465345724 | B8: #15228 | C8: cyung@wustl.edu | E8: Casey Yung | F8: 18 Warford Terrace Orinda United States | G8: Orinda | H8: California | I8: 94563 | J8: United States | K8: Nationwide Ship to School | L8: Nationwide Ship to School | M8: 49 | N8: University Housing | O8: 441 | P8: 45883 | Q8: 09:00 AM to 11:00 AM | T8: University Housing | U8: Park | V8: 441 | X8: 45883 | Y8: 09:00 AM to 11:00 AM
A9: https://utrucking.com/admin/orders/5898488905916 | B9: #15229 | C9: acaitlin@wustl.edu | E9: Caitlin Alfaro | F9: 28 Black Pine Lane Lumberton United States | G9: Lumberton | H9: New Jersey | I9: 8048 | J9: United States | K9: Nationwide Ship to School | L9: Nationwide Ship to School | M9: 49 | N9: University Housing | O9: 104C-b | P9: 45883 | Q9: 09:00 AM to 11:00 AM | T9: University Housing | U9: Millbrook Bldg. 2 | V9: 104C-b | X9: 45883 | Y9: 09:00 AM to 11:00 AM
A10: https://utrucking.com/admin/orders/5898491166908 | B10: #15230 | C10: acaitlin@wustl.edu | E10: Caitlin Alfaro | F10: 28 Black Pine Lane Lumberton United States | G10: Lumberton | H10: New Jersey | I10: 8048 | J10: United States | K10: Storage Item Return | M10: 1 | N10: University Housing | O10: 104C-b | P10: 45883 | Q10: 09:00 AM to 11:00 AM | T10: University Housing | U10: Millbrook Bldg. 2 | V10: 104C-b | X10: 45883 | Y10: 09:00 AM to 11:00 AM
A11: https://utrucking.com/admin/orders/5898525311164 | B11: #15232 | C11: m.h.ryu@wustl.edu | E11: Maya Ryu | F11: 4914 41st Street Northwest Washington United States | G11: Washington | H11: District of Columbia | I11: 20016 | J11: United States | K11: Appliance Rental | L11: Double-Door Mini Fridge | M11: 145 | O11: 201A - a | P11: 45883 | U11: Millbrook Bldg. 3 | V11: 201A - a | X11: 45883
A12: https://utrucking.com/admin/orders/5898994155708 | B12: #15236 | C12: a.kalbag@wustl.edu | E12: Arjun Kalbag | F12: 152 East 87th Street New York United States | G12: New York | H12: Connecticut | I12: 6880 | J12: United States | K12: Appliance Rental | L12: Double-Door Mini Fridge + Microwave | M12: 210 | O12: 3341 | P12: 45885 | U12: Umrath | V12: 3341 | X12: 45885
A13: https://utrucking.com/admin/orders/5899120771260 | B13: #15237 | D13: =12059223707 -> 12059223707 | E13: Olivia Vanlandingham | F13: 309 Le Jeune Way Birmingham United States | G13: Birmingham | H13: Alabama | I13: 35209 | J13: United States | K13: Appliance Rental | L13: Double-Door Mini Fridge | M13: 145 | O13: 380 | P13: 45875 | U13: Mudd | V13: 380 | X13: 45875
A14: https://utrucking.com/admin/orders/5899149574332 | B14: #15239 | C14: f.perez@wustl.edu | E14: Francisco Perez | F14: 4747 N Kenneth Ave Apt 3 Chicago United States | G14: Chicago | H14: Illinois | I14: 60630 | J14: United States | K14: Storage Item Return | M14: 1 | N14: University Housing | O14: 110 | P14: 45883 | Q14: 09:00 AM to 11:00 AM | T14: University Housing | U14: House 5 (Hamsini) | V14: 110 | X14: 45883 | Y14: 09:00 AM to 11:00 AM
A15: https://utrucking.com/admin/orders/5899278713020 | B15: #15242 | C15: samanthar@wustl.edu | D15: 3124809444 | E15: Jonathan Rosenberg | G15: Highland Park | H15: Illinois | I15: 60035 | J15: United States | K15: Appliance Rental | L15: Double-Door Mini Fridge + Microwave | M15: 210 | O15: 3321 | P15: 45883 | U15: Danforth | V15: 3321 | X15: 45883
A16: https://utrucking.com/admin/orders/5899279007932 | B16: #15243 | C16: washko@wustl.edu | D16: 8573600811 | E16: William Washko | G16: West Roxbury | H16: Massachusetts | I16: 2132 | J16: United States | K16: Nationwide Ship to School | L16: Nationwide Ship to School | M16: 49 | N16: University Housing | O16: 1084 - a | P16: 45883 | Q16: 09:00 AM to 11:00 AM | T16: University Housing | U16: Eliot A | V16: 1084 - a | X16: 45883 | Y16: 09:00 AM to 11:00 AM
A17: https://utrucking.com/admin/orders/5899315642556 | B17: #15244 | D17: 9788061822 | E17: Emily Kobelski | G17: Andover | H17: Massachusetts | I17: 1810 | J17: United States | K17: Storage Item Return | M17: 1 | N17: University Housing | O17: 4160 | P17: 45890 | Q17: 09:00 AM to 11:00 AM | T17: University Housing | U17: Village House | V17: 4160 | X17: 45890 | Y17: 09:00 AM to 11:00 AM
A18: https://utrucking.com/admin/orders/5899375313084 | B18: #15245 | D18: 6504683885 | E18: jackie shurslep | G18: Larchmont | H18: New York | I18: 10538 | J18: United States | K18: Appliance Rental | L18: Double-Door Mini Fridge | M18: 145 | O18: 1116 | P18: 45883 | U18: Lien | V18: 1116 | X18: 45883
A19: https://utrucking.com/admin/orders/5899380981948 | B19: #15246 | C19: h.serene@wustl.edu | D19: 6788767305 | E19: Erica Harris | G19: Lawrenceville | H19: Georgia | I19: 30043 | J19: United States | K19: Storage Item Return | M19: 1 | N19: University Housing | O19: 210 | P19: 45891 | Q19: 09:00 AM to 11:00 AM | T19: University Housing | U19: House 1 (Alpha Delta Phi) | V19: 210 | X19: 45891 | Y19: 09:00 AM to 11:00 AM
A20: https://utrucking.com/admin/orders/5899380981948 | B20: #15246 | C20: h.serene@wustl.edu | D20: 6788767305 | E20: Erica Harris | G20: Lawrenceville | H20: Georgia | I20: 30043 | J20: United States | K20: Appliance Rental | L20: Double-Door Mini Fridge + Microwave | M20: 210 | O20: 210 | P20: 45883 | U20: House 1 (Alpha Delta Phi) | V20: 210 | X20: 45883
A21: https://utrucking.com/admin/orders/5899398512828 | B21: #15247 | C21: atticks@wustl.edu | D21: 14104994906 | E21: Andrea Atticks | G21: Cockeysville | H21: Maryland | I21: 21030-1724 | J21: United States | K21: Appliance Rental | L21: Double-Door Mini Fridge + Microwave | M21: 210 | O21: 1112 | P21: 45883 | U21: Koenig | V21: 1112 | X21: 45883
A22: https://utrucking.com/admin/orders/5899539480764 | B22: #15248 | C22: marci_sherman@hotmail.com | E22: Marci Rosenblatt | G22: Lafayette | H22: Missouri | I22: 94549 | J22: United States | K22: Nationwide Ship to School | L22: Nationwide Ship to School | M22: 49 | N22: University Housing | O22: 441b | P22: 45883 | Q22: 09:00 AM to 11:00 AM | T22: University Housing | U22: Park | V22: 441b | X22: 45883 | Y22: 09:00 AM to 11:00 AM
A23: https://utrucking.com/admin/orders/5899755684028 | B23: #15250 | C23: mhwtan@gmail.com | D23: 3106061350 | E23: Tan 18 Misty Acres Rd | G23: United States | H23: California | I23: 90274 | J23: United States | K23: Appliance Rental | L23: Double-Door Mini Fridge | M23: 145 | O23: 2208 | P23: 45883 | U23: Dardick | V23: 2208 | X23: 45883
A24: https://utrucking.com/admin/orders/5899777736892 | B24: #15251 | C24: g.lanzillo@wustl.edu | D24: 3022334790 | E24: Gemma Lanzillo | G24: Stafford | H24: Virginia | I24: 22554 | J24: United States | K24: Storage Item Return | M24: 1 | N24: University Housing | O24: 2052-a | P24: 45883 | Q24: 09:00 AM to 11:00 AM | T24: University Housing | U24: Shepley | V24: 2052-a | X24: 45883 | Y24: 09:00 AM to 11:00 AM
A25: https://utrucking.com/admin/orders/5899791564988 | B25: #15252 | C25: fike@wustl.edu | D25: 7737441350 | E25: Lisa Fike | G25: Plainfield | H25: Illinois | I25: 60585 | J25: United States | K25: Appliance Rental | L25: Double-Door Mini Fridge | M25: 145 | O25: 4032 | P25: 45883 | U25: Wheeler | V25: 4032 | X25: 45883
A26: https://utrucking.com/admin/orders/5899837145276 | B26: #15253 | C26: lisapetlak@hotmail.com | D26: 13103673106 | E26: Lisa Petlak | G26: Los Angeles | H26: California | I26: 90035-3218 | J26: United States | K26: Appliance Rental | L26: Double-Door Mini Fridge + Microwave | M26: 210 | O26: 3305 | P26: 45883 | U26: Dardick | V26: 3305 | X26: 45883
A27: https://utrucking.com/admin/orders/5900006424764 | B27: #15254 | D27: 7033109100 | E27: Emily Pocrass | F27: 1870 Patrick Henry Drive | G27: Arlington | H27: Virginia | I27: 22205 | J27: United States | K27: Appliance Rental | L27: Double-Door Mini Fridge + Microwave | M27: 210 | O27: 232 | P27: 45883 | U27: Umrath | V27: 232 | X27: 45883
A28: https://utrucking.com/admin/orders/5900080283836 | B28: #15255 | C28: lorieclassner@gmail.com | D28: 3107019782 | E28: Ethan Lassner | F28: 13548 Valley Vista Boulevard | G28: Sherman Oaks | H28: California | I28: 91423 | J28: United States | K28: Appliance Rental | L28: Double-Door Mini Fridge + Microwave | M28: 210 | O28: 1082-a | P28: 45883 | U28: Eliot A | V28: 1082-a | X28: 45883
A29: https://utrucking.com/admin/orders/5900080283836 | B29: #15255 | C29: lorieclassner@gmail.com | D29: 3107019782 | E29: Ethan Lassner | F29: 13548 Valley Vista Boulevard | G29: Sherman Oaks | H29: California | I29: 91423 | J29: United States | K29: Nationwide Ship to School | L29: Nationwide Ship to School | M29: 49 | N29: University Housing | O29: 1082-a | P29: 45883 | Q29: 09:00 AM to 11:00 AM | T29: University Housing | U29: Eliot A | V29: 1082-a | X29: 45883 | Y29: 09:00 AM to 11:00 AM
A30: https://utrucking.com/admin/orders/5900083265724 | B30: #15256 | C30: b.e.veiel@wustl.edu | D30: 4102586632 | E30: Lori Veiel | F30: 448 Arundel Beach Road | G30: Severna Park | H30: Maryland | I30: 21146 | J30: United States | K30: Appliance Rental | L30: Double-Door Mini Fridge | M30: 145 | O30: 3373-a | P30: 45883 | U30: Liggett | V30: 3373-a | X30: 45883
A31: https://utrucking.com/admin/orders/5900089852092 | B31: #15257 | C31: hgrossman05@gmail.com | D31: 12013100288 | E31: Harrison Grossman | F31: 17019 Brookwood Dr | G31: Boca Raton | H31: Florida | I31: 33496 | J31: United States | K31: Storage Item Return | M31: 1 | N31: Non-University Housing | P31: 45871 | Q31: 11:00 AM to 01:00 PM | T31: Non-University Housing | X31: 45871 | Y31: 11:00 AM to 01:00 PM | AA31: 100 N Kingshighway Blvd St Louis MO 63108
A32: https://utrucking.com/admin/orders/5900123701436 | B32: #15259 | C32: katiemeggers@gmail.com | D32: 17148848990 | E32: Julie Meggers | F32: 1815 Port Ashley Place | G32: Newport Beach | H32: California | I32: 92660-5337 | J32: United States | K32: Nationwide Ship to School | L32: Nationwide Ship to School | M32: 49 | N32: University Housing | O32: L230-a | P32: 45883 | Q32: 09:00 AM to 11:00 AM | T32: University Housing | U32: Umrath | V32: L230-a | X32: 45883 | Y32: 09:00 AM to 11:00 AM
A33: https://utrucking.com/admin/orders/5900123734204 | B33: #15260 | C33: j.todfield118@gmail.com | D33: 19178821115 | E33: Jamie pastrano | F33: 70 Little West StApt 24F | G33: New York | H33: New York | I33: 10004 | J33: United States | K33: Tri-State Area Home Pickups | M33: 49 | N33: University Housing | O33: 3309-a | P33: 45883 | T33: University Housing | U33: Dardick | V33: 3309-a | X33: 45883 | Z33: $100 per item [Included]
A34: https://utrucking.com/admin/orders/5900186910908 | B34: #15263 | C34: allisonstern@hotmail.com | D34: 3102463451 | E34: Allison Samek | F34: 498 South Spalding Drive | G34: Beverly Hills | H34: California | I34: 90212 | J34: United States | K34: Appliance Rental | L34: Double-Door Mini Fridge + Microwave | M34: 210 | O34: 219A | P34: 45883 | U34: Lee | V34: 219A | X34: 45883
A35: https://utrucking.com/admin/orders/5900228886716 | B35: #15264 | C35: chanel7557@yahoo.com | D35: 3123440050 | E35: Chanel Bell | F35: 705 McCardle Drive | G35: West Chester | H35: Pennsylvania | I35: 19380 | J35: United States | K35: Appliance Rental | L35: Microwave Only | M35: 65 | O35: 2220 | P35: 45883 | U35: Lien | V35: 2220 | X35: 45883
A36: https://utrucking.com/admin/orders/5900252807356 | B36: #15265 | C36: walkerfamilycinco@yahoo.com | D36: 9193338112 | E36: Layla Walker | F36: 1900 Fieldstone Way | G36: Frederick | H36: Maryland | I36: 21702 | J36: United States | K36: Nationwide Ship to School | L36: Nationwide Ship to School | M36: 49 | N36: University Housing | O36: 491A | P36: 45883 | Q36: 09:00 AM to 11:00 AM | T36: University Housing | U36: Park | V36: 491A | X36: 45883 | Y36: 09:00 AM to 11:00 AM
A37: https://utrucking.com/admin/orders/5900316573884 | B37: #15266 | C37: p.rex@wustl.edu | D37: 2242163846 | E37: Rex Paster | F37: 305 Grove Street | G37: Glencoe | H37: Illinois | I37: 60022 | J37: United States | K37: Appliance Rental | L37: Standard Mini Fridge | M37: 115 | O37: 3339 | P37: 45852 | U37: Umrath | V37: 3339 | X37: 45852
A38: https://utrucking.com/admin/orders/5900318474428 | B38: #15267 | D38: 9177707102 | E38: stacey zoland | F38: 9 foxhall place | G38: scarsdale | H38: New York | I38: 10583 | J38: United States | K38: Appliance Rental | L38: Double-Door Mini Fridge + Microwave | M38: 210 | O38: 133-a | P38: 45883 | U38: Dauten | V38: 133-a | X38: 45883
A39: https://utrucking.com/admin/orders/5900342067388 | B39: #15268 | C39: d.mingyue@wustl.edu | D39: 13144377750 | E39: Mingyue Ding | F39: 6985 Snow Way Drive | G39: St. Louis | H39: Missouri | I39: 63130 | J39: United States | K39: Storage Item Return | M39: 1 | N39: University Housing | O39: 209 - a | P39: 45883 | Q39: 09:00 AM to 11:00 AM | T39: University Housing | U39: House 1 (Alpha Delta Phi) | V39: 209 - a | X39: 45883 | Y39: 09:00 AM to 11:00 AM
A40: https://utrucking.com/admin/orders/5900610175164 | B40: #15269 | C40: sophia.hasan@icloud.com | D40: 7082505700 | E40: Sophia Hasan | F40: 111 Singletree Road | G40: Orland Park | H40: Illinois | I40: 60467 | J40: United States | K40: Nationwide Ship to School | L40: Nationwide Ship to School | M40: 49 | N40: University Housing | O40: 309 | P40: 45883 | Q40: 09:00 AM to 11:00 AM | T40: University Housing | U40: Lee | V40: 309 | X40: 45883 | Y40: 09:00 AM to 11:00 AM
...

Sheet TEST
A1: Order URL | B1: Order Name | C1: Email | D1: Shipping Name | E1: Address | F1: City | G1: State/Province | H1: Zip | I1: Country | J1: Product Name | K1: Product SKU | L1: Product Price | M1: Pickup Date | N1: Pickup Time | O1: Pickup Location | P1: Building | Q1: Room Number | R1: Off-Campus Address | S1: Delivery Location | T1: Delivery Date | U1: Delivery Time | V1: Ship From Address | W1: Move Date | X1: Move Type | Y1: Moving from address or location_copy | Z1: Moving to address or location | AA1: Note | AB1: Insurance | AC1: Pickup Address | AD1: Location Type | AE1: Non-University Housing Address
A2: https://utrucking.com/admin/orders/5900755337404 | B2: #15275 | C2: orbucho2006@gmail.com | J2: Storage Item Return | L2: 1 | R2: 7036 Forsyth Blvd | S2: Non-University Housing | T2: 45875 | U2: 12:00 PM to 02:00 PM
A3: https://utrucking.com/admin/orders/5900755337404 | B3: #15275 | C3: orbucho2006@gmail.com | D3: Olivia Orbuch | E3: 1723 s corning street | F3: Los Angles | G3: California | H3: 90035 | I3: United States | J3: Storage Item Return | L3: 1 | R3: 7036 Forsyth Blvd | S3: Non-University Housing | T3: 45875 | U3: 12:00 PM to 02:00 PM

Sheet Order Edits
A1: Order # | B1: Change Type | C1: New Date | D1: New Time | E1: New Room | F1: New Building | G1: New Off-Campus Adress | H1: Notes | I1: Edited on MAIN? | J1: Edited Shopify Note? | K1: Reported On | L1: Edited on | M1: Edited By
A2: #15222 | B2: Date, Room, Building | C2: 45884 | E2: 412 | F2: Dauten | I2: TRUE | J2: TRUE | L2: 45853 | M2: Ahmed
A3: #15223 | B3: Date, Room, Building | C3: 45885 | E3: 3304 | F3: Koenig | I3: TRUE | J3: TRUE | L3: 45853 | M3: Ahmed
A4: #15224 | B4: Date, Room, Building | C4: 45884 | E4: 4421 | F4: Dardick | I4: TRUE | J4: TRUE | L4: 45853 | M4: Ahmed
A5: #15261 | B5: Date, Room, Building | C5: 45884 | E5: 3310 | F5: Koenig | I5: TRUE | J5: TRUE | L5: 45853 | M5: Ahmed
A6: #15262 | B6: Room, Building | E6: 2224 | F6: Lien | I6: TRUE | J6: TRUE | L6: 45853 | M6: Ahmed
A7: #15266 | B7: Date | C7: 45883 | I7: TRUE | J7: TRUE | L7: 45853 | M7: Ahmed
A8: #15284 | B8: Date | C8: 45883 | I8: TRUE | J8: TRUE | L8: 45853 | M8: Ahmed
A9: #15327 | B9: Date, Time | C9: 45888 | D9: 45911 | H9: wants delivery on August 19th, 9-11am | I9: TRUE | J9: TRUE | L9: 45853 | M9: Ahmed
A10: #15339 | B10: Date | C10: 45883 | I10: TRUE | J10: TRUE | L10: 45853 | M10: Ahmed
A11: #15363 | B11: Service-Note | H11: switched from tsa to nsts | I11: TRUE | J11: TRUE | L11: 45859 | M11: Ahmed
A12: #15338 | B12: Service-Note | H12: removed nsts from order, using tsa (although tsa never showed up on this sheet) | I12: TRUE | J12: TRUE | L12: 45859 | M12: Ahmed
A13: #15391 | B13: Date | C13: 45883 | I13: TRUE | J13: TRUE | L13: 45859 | M13: Ahmed
A14: #15071 | B14: Room, Building | E14: 3309 | F14: Umrath | I14: TRUE | J14: TRUE | L14: 45859 | M14: Ahmed
A15: #15433 | B15: Cancelled | H15: canceled their order | I15: TRUE | J15: TRUE
A16: #14983 | B16: Room, Building | E16: 4427 | F16: Danforth | I16: TRUE | J16: TRUE | K16: 45857 | L16: 45859 | M16: Ahmed
A17: #14171 | B17: Room, Building | E17: 3331 | F17: Lien | I17: TRUE | J17: TRUE | K17: 45857 | L17: 45859 | M17: Ahmed
A18: #15064 | B18: Date, Room, Building, Product | C18: 45891 | E18: 3062 | F18: Gregg | H18: not on main, add to main, SWITCH TO CHEF SIZE FRIDGE | I18: TRUE | J18: TRUE | K18: 45858 | L18: 45859 | M18: Ahmed
A19: #15327 | B19: date, time | C19: 45888 | D19: 45942 | I19: TRUE | J19: TRUE | K19: 45859
A20: #15548 | B20: date | C20: 45881 | I20: TRUE | J20: TRUE | K20: 45859 | L20: 45860 | M20: Ahmed
A21: #15574 | B21: Date | C21: 45860 | H21: Switch spec ops to 7/22 since calendar wouldn't let me select earlier than 7/23 | I21: TRUE | J21: TRUE | K21: 45859 | L21: 45860 | M21: Ahmed
A22: #14853 | B22: room, building | E22: 372 | F22: Park | I22: TRUE | J22: TRUE | L22: 45863 | M22: Ahmed
A23: #15114 | B23: room, building | E23: 242-b | F23: Dauten | I23: TRUE | J23: TRUE | L23: 45863 | M23: Ahmed
A24: #15133 | B24: room, building | E24: L-237 | F24: Umrath | I24: TRUE | J24: TRUE | L24: 45863 | M24: Ahmed
A25: #15550 | B25: date | C25: 45890 | I25: TRUE | J25: TRUE | L25: 45863 | M25: Ahmed
A26: #15581 | B26: date, time | C26: 45887 | D26: 45911 | I26: TRUE | J26: TRUE | L26: 45863 | M26: Ahmed
A27: #15271 | B27: date | C27: 45876 | I27: TRUE | J27: TRUE | L27: 45863 | M27: Ahmed
A28: #14588 | B28: room, building | E28: 4419 | F28: Danforth | I28: TRUE | J28: TRUE | L28: 45863 | M28: Ahmed
A29: #15582 | B29: date, time | C29: 45891 | D29: 45941 | I29: TRUE | J29: TRUE | L29: 45863 | M29: Ahmed
A30: #15103 | B30: room, building | E30: 413 | F30: Myers | I30: TRUE | J30: TRUE | L30: 45863 | M30: Ahmed
A31: #15704 | B31: service note | H31: switch to tri-state home pickup | I31: TRUE | J31: TRUE | L31: 45863 | M31: Ahmed
A32: #15711 | B32: cancelled | H32: canceled their order | I32: TRUE | J32: TRUE | L32: 45863 | M32: Ahmed
A33: #15539 | B33: room, building | E33: 3319 | F33: Danforth | I33: TRUE | J33: TRUE | L33: 45865 | M33: Ahmed
A34: #15148 | B34: room, building | E34: 3323 | F34: Umrath | I34: TRUE | J34: TRUE | L34: 45865 | M34: Ahmed
A35: #14996 | B35: re-add and edit housing | E35: 3301 | F35: Koenig | H35: Double Door mini fridge (order was fulfilled after summer delivery, need to make sure it is re-added and housing is changed to koenig) | I35: TRUE | J35: TRUE | L35: 45865 | M35: Ahmed
A36: #14341 | B36: room, building | E36: 3302 | F36: Umrath | I36: TRUE | J36: TRUE | L36: 45865 | M36: Ahmed
A37: #14342 | B37: room, building | E37: 3302 | F37: Umrath | I37: TRUE | J37: TRUE | L37: 45865 | M37: Ahmed
A38: #15079 | B38: room, building | E38: 2240 | F38: Umrath | I38: TRUE | J38: TRUE | L38: 45865 | M38: Ahmed
A39: #15487 | B39: service note | H39: cancel microwave, keep fridge | I39: TRUE | J39: TRUE | L39: 45865 | M39: Ahmed
A40: #15514 | B40: date, room, building | C40: 45891 | E40: 1051 | F40: Lopata | I40: TRUE | J40: TRUE | L40: 45865 | M40: Ahmed
...

Sheet Kit Delivery Status
A1: =IFERROR(__xludf.DUMMYFUNCTION("IMPORTRANGE(""1x5MQbsCFMJX5eafA6uoFF0nU4qfvCaK-2EyZNPs__kM"", ""'Kit History'!A:Z"")"),"ID") -> ID | B1: =IFERROR(__xludf.DUMMYFUNCTION("""COMPUTED_VALUE"""),"Date") -> Date | C1: =IFERROR(__xludf.DUMMYFUNCTION("""COMPUTED_VALUE"""),"Mode") -> Mode | D1: =IFERROR(__xludf.DUMMYFUNCTION("""COMPUTED_VALUE"""),"Truck") -> Truck | E1: =IFERROR(__xludf.DUMMYFUNCTION("""COMPUTED_VALUE"""),"Building") -> Building | F1: =IFERROR(__xludf.DUMMYFUNCTION("""COMPUTED_VALUE"""),"Room") -> Room | G1: =IFERROR(__xludf.DUMMYFUNCTION("""COMPUTED_VALUE"""),"Student") -> Student | H1: =IFERROR(__xludf.DUMMYFUNCTION("""COMPUTED_VALUE"""),"Phone") -> Phone | I1: =IFERROR(__xludf.DUMMYFUNCTION("""COMPUTED_VALUE"""),"Time Slot") -> Time Slot | J1: =IFERROR(__xludf.DUMMYFUNCTION("""COMPUTED_VALUE"""),"Kits") -> Kits | K1: =IFERROR(__xludf.DUMMYFUNCTION("""COMPUTED_VALUE"""),"Status") -> Status | L1: =IFERROR(__xludf.DUMMYFUNCTION("""COMPUTED_VALUE"""),"Mover Notes") -> Mover Notes | M1: =IFERROR(__xludf.DUMMYFUNCTION("""COMPUTED_VALUE"""),"Completed At") -> Completed At | N1: =IFERROR(__xludf.DUMMYFUNCTION("""COMPUTED_VALUE"""),"Sort Order") -> Sort Order | O1: =IFERROR(__xludf.DUMMYFUNCTION("""COMPUTED_VALUE"""),"Address") -> Address | P1: =IFERROR(__xludf.DUMMYFUNCTION("""COMPUTED_VALUE"""),"Service") -> Service | Q1: =IFERROR(__xludf.DUMMYFUNCTION("""COMPUTED_VALUE"""),"Customer Note") -> Customer Note | R1: =IFERROR(__xludf.DUMMYFUNCTION("""COMPUTED_VALUE"""),"Product") -> Product | S1: =IFERROR(__xludf.DUMMYFUNCTION("""COMPUTED_VALUE"""),"Photos") -> Photos | T1: =IFERROR(__xludf.DUMMYFUNCTION("""COMPUTED_VALUE"""),"Archived On") -> Archived On | U1: =IFERROR(__xludf.DUMMYFUNCTION("""COMPUTED_VALUE"""),"Order Number") -> Order Number
A2: =IFERROR(__xludf.DUMMYFUNCTION("""COMPUTED_VALUE"""),"KIT-#17764") -> KIT-#17764 | B2: =IFERROR(__xludf.DUMMYFUNCTION("""COMPUTED_VALUE"""),46139.0) -> 46139 | C2: =IFERROR(__xludf.DUMMYFUNCTION("""COMPUTED_VALUE"""),"Kit Delivery") -> Kit Delivery | D2: =IFERROR(__xludf.DUMMYFUNCTION("""COMPUTED_VALUE"""),1.0) -> 1 | E2: =IFERROR(__xludf.DUMMYFUNCTION("""COMPUTED_VALUE"""),"Off-Campus") -> Off-Campus | G2: =IFERROR(__xludf.DUMMYFUNCTION("""COMPUTED_VALUE"""),"Yujin He") -> Yujin He | H2: =IFERROR(__xludf.DUMMYFUNCTION("""COMPUTED_VALUE"""),3.144377856E9) -> 3144377856 | I2: =IFERROR(__xludf.DUMMYFUNCTION("""COMPUTED_VALUE"""),"12PM-2PM") -> 12PM-2PM | J2: =IFERROR(__xludf.DUMMYFUNCTION("""COMPUTED_VALUE"""),0.0) -> 0 | K2: =IFERROR(__xludf.DUMMYFUNCTION("""COMPUTED_VALUE"""),"Complete") -> Complete | L2: =IFERROR(__xludf.DUMMYFUNCTION("""COMPUTED_VALUE"""),"no kit") -> no kit | N2: =IFERROR(__xludf.DUMMYFUNCTION("""COMPUTED_VALUE"""),228.0) -> 228 | O2: =IFERROR(__xludf.DUMMYFUNCTION("""COMPUTED_VALUE"""),"605 Leland Ave, University City, MO, 63130; University Squares Apartment") -> 605 Leland Ave, University City, MO, 63130; University Squares Apartment | P2: =IFERROR(__xludf.DUMMYFUNCTION("""COMPUTED_VALUE"""),"Kit Delivery") -> Kit Delivery | T2: =IFERROR(__xludf.DUMMYFUNCTION("""COMPUTED_VALUE"""),46137.738217592596) -> 46137.738
A3: =IFERROR(__xludf.DUMMYFUNCTION("""COMPUTED_VALUE"""),"KIT-#17350") -> KIT-#17350 | B3: =IFERROR(__xludf.DUMMYFUNCTION("""COMPUTED_VALUE"""),46140.0) -> 46140 | C3: =IFERROR(__xludf.DUMMYFUNCTION("""COMPUTED_VALUE"""),"Kit Delivery") -> Kit Delivery | D3: =IFERROR(__xludf.DUMMYFUNCTION("""COMPUTED_VALUE"""),1.0) -> 1 | E3: =IFERROR(__xludf.DUMMYFUNCTION("""COMPUTED_VALUE"""),"LL6300") -> LL6300 | F3: =IFERROR(__xludf.DUMMYFUNCTION("""COMPUTED_VALUE"""),"304C") -> 304C | G3: =IFERROR(__xludf.DUMMYFUNCTION("""COMPUTED_VALUE"""),"Nena Tesinsky") -> Nena Tesinsky | H3: =IFERROR(__xludf.DUMMYFUNCTION("""COMPUTED_VALUE"""),9.195618234E9) -> 9195618234 | I3: =IFERROR(__xludf.DUMMYFUNCTION("""COMPUTED_VALUE"""),"3PM-5PM") -> 3PM-5PM | J3: =IFERROR(__xludf.DUMMYFUNCTION("""COMPUTED_VALUE"""),0.0) -> 0 | K3: =IFERROR(__xludf.DUMMYFUNCTION("""COMPUTED_VALUE"""),"Complete") -> Complete | N3: =IFERROR(__xludf.DUMMYFUNCTION("""COMPUTED_VALUE"""),37.0) -> 37 | P3: =IFERROR(__xludf.DUMMYFUNCTION("""COMPUTED_VALUE"""),"Kit Delivery") -> Kit Delivery | S3: =IFERROR(__xludf.DUMMYFUNCTION("""COMPUTED_VALUE"""),46122.53804398148) -> 46122.538
A4: =IFERROR(__xludf.DUMMYFUNCTION("""COMPUTED_VALUE"""),"KIT-#17765") -> KIT-#17765 | B4: =IFERROR(__xludf.DUMMYFUNCTION("""COMPUTED_VALUE"""),46143.0) -> 46143 | C4: =IFERROR(__xludf.DUMMYFUNCTION("""COMPUTED_VALUE"""),"Kit Delivery") -> Kit Delivery | D4: =IFERROR(__xludf.DUMMYFUNCTION("""COMPUTED_VALUE"""),1.0) -> 1 | E4: =IFERROR(__xludf.DUMMYFUNCTION("""COMPUTED_VALUE"""),"Park") -> Park | F4: =IFERROR(__xludf.DUMMYFUNCTION("""COMPUTED_VALUE"""),162.0) -> 162 | G4: =IFERROR(__xludf.DUMMYFUNCTION("""COMPUTED_VALUE"""),"Casey Ference") -> Casey Ference | H4: =IFERROR(__xludf.DUMMYFUNCTION("""COMPUTED_VALUE"""),"(917) 733-1526") -> (917) 733-1526 | I4: =IFERROR(__xludf.DUMMYFUNCTION("""COMPUTED_VALUE"""),"9AM-11AM") -> 9AM-11AM | J4: =IFERROR(__xludf.DUMMYFUNCTION("""COMPUTED_VALUE"""),0.0) -> 0 | K4: =IFERROR(__xludf.DUMMYFUNCTION("""COMPUTED_VALUE"""),"Complete") -> Complete | L4: =IFERROR(__xludf.DUMMYFUNCTION("""COMPUTED_VALUE"""),"no kit") -> no kit | N4: =IFERROR(__xludf.DUMMYFUNCTION("""COMPUTED_VALUE"""),49.0) -> 49 | O4: =IFERROR(__xludf.DUMMYFUNCTION("""COMPUTED_VALUE"""),"8 John Street Demarest, NJ 07627") -> 8 John Street Demarest, NJ 07627 | P4: =IFERROR(__xludf.DUMMYFUNCTION("""COMPUTED_VALUE"""),"Kit Delivery") -> Kit Delivery | T4: =IFERROR(__xludf.DUMMYFUNCTION("""COMPUTED_VALUE"""),46137.738217592596) -> 46137.738
A5: =IFERROR(__xludf.DUMMYFUNCTION("""COMPUTED_VALUE"""),"KIT-#17767") -> KIT-#17767 | B5: =IFERROR(__xludf.DUMMYFUNCTION("""COMPUTED_VALUE"""),46143.0) -> 46143 | C5: =IFERROR(__xludf.DUMMYFUNCTION("""COMPUTED_VALUE"""),"Kit Delivery") -> Kit Delivery | D5: =IFERROR(__xludf.DUMMYFUNCTION("""COMPUTED_VALUE"""),2.0) -> 2 | E5: =IFERROR(__xludf.DUMMYFUNCTION("""COMPUTED_VALUE"""),"Umrath") -> Umrath | F5: =IFERROR(__xludf.DUMMYFUNCTION("""COMPUTED_VALUE"""),"L239") -> L239 | G5: =IFERROR(__xludf.DUMMYFUNCTION("""COMPUTED_VALUE"""),"Mia Galpern") -> Mia Galpern | H5: =IFERROR(__xludf.DUMMYFUNCTION("""COMPUTED_VALUE"""),9.177155789E9) -> 9177155789 | I5: =IFERROR(__xludf.DUMMYFUNCTION("""COMPUTED_VALUE"""),"10AM-12PM") -> 10AM-12PM | J5: =IFERROR(__xludf.DUMMYFUNCTION("""COMPUTED_VALUE"""),0.0) -> 0 | K5: =IFERROR(__xludf.DUMMYFUNCTION("""COMPUTED_VALUE"""),"Complete") -> Complete | N5: =IFERROR(__xludf.DUMMYFUNCTION("""COMPUTED_VALUE"""),85.0) -> 85 | O5: =IFERROR(__xludf.DUMMYFUNCTION("""COMPUTED_VALUE"""),"66 Leonard street 9b New York, NY 10013") -> 66 Leonard street 9b New York, NY 10013 | P5: =IFERROR(__xludf.DUMMYFUNCTION("""COMPUTED_VALUE"""),"Kit Delivery") -> Kit Delivery | T5: =IFERROR(__xludf.DUMMYFUNCTION("""COMPUTED_VALUE"""),46138.009050925924) -> 46138.009
A6: =IFERROR(__xludf.DUMMYFUNCTION("""COMPUTED_VALUE"""),"KIT-#17508") -> KIT-#17508 | B6: =IFERROR(__xludf.DUMMYFUNCTION("""COMPUTED_VALUE"""),46144.0) -> 46144 | C6: =IFERROR(__xludf.DUMMYFUNCTION("""COMPUTED_VALUE"""),"Kit Delivery") -> Kit Delivery | D6: =IFERROR(__xludf.DUMMYFUNCTION("""COMPUTED_VALUE"""),3.0) -> 3 | E6: =IFERROR(__xludf.DUMMYFUNCTION("""COMPUTED_VALUE"""),"Koenig") -> Koenig | F6: =IFERROR(__xludf.DUMMYFUNCTION("""COMPUTED_VALUE"""),4413.0) -> 4413 | G6: =IFERROR(__xludf.DUMMYFUNCTION("""COMPUTED_VALUE"""),"Ava Virmani") -> Ava Virmani | H6: =IFERROR(__xludf.DUMMYFUNCTION("""COMPUTED_VALUE"""),3.123998535E9) -> 3123998535 | I6: =IFERROR(__xludf.DUMMYFUNCTION("""COMPUTED_VALUE"""),"2PM-4PM") -> 2PM-4PM | J6: =IFERROR(__xludf.DUMMYFUNCTION("""COMPUTED_VALUE"""),0.0) -> 0 | K6: =IFERROR(__xludf.DUMMYFUNCTION("""COMPUTED_VALUE"""),"Complete") -> Complete | L6: =IFERROR(__xludf.DUMMYFUNCTION("""COMPUTED_VALUE"""),"No kit, don't SMS") -> No kit, don't SMS | M6: =IFERROR(__xludf.DUMMYFUNCTION("""COMPUTED_VALUE"""),46130.421076388884) -> 46130.421 | N6: =IFERROR(__xludf.DUMMYFUNCTION("""COMPUTED_VALUE"""),212.0) -> 212 | P6: =IFERROR(__xludf.DUMMYFUNCTION("""COMPUTED_VALUE"""),"Kit Delivery") -> Kit Delivery | S6: =IFERROR(__xludf.DUMMYFUNCTION("""COMPUTED_VALUE"""),"Dispatch_Images/KIT--17508.Photos.150618.jpg") -> Dispatch_Images/KIT--17508.Photos.150618.jpg | T6: =IFERROR(__xludf.DUMMYFUNCTION("""COMPUTED_VALUE"""),46130.42574074074) -> 46130.426
A7: =IFERROR(__xludf.DUMMYFUNCTION("""COMPUTED_VALUE"""),"KIT-#18101") -> KIT-#18101 | B7: =IFERROR(__xludf.DUMMYFUNCTION("""COMPUTED_VALUE"""),46144.0) -> 46144 | C7: =IFERROR(__xludf.DUMMYFUNCTION("""COMPUTED_VALUE"""),"Kit Delivery") -> Kit Delivery | D7: =IFERROR(__xludf.DUMMYFUNCTION("""COMPUTED_VALUE"""),2.0) -> 2 | E7: =IFERROR(__xludf.DUMMYFUNCTION("""COMPUTED_VALUE"""),"Eliot B") -> Eliot B | F7: =IFERROR(__xludf.DUMMYFUNCTION("""COMPUTED_VALUE"""),3060.0) -> 3060 | G7: =IFERROR(__xludf.DUMMYFUNCTION("""COMPUTED_VALUE"""),"Juliet Quisenberry") -> Juliet Quisenberry | H7: =IFERROR(__xludf.DUMMYFUNCTION("""COMPUTED_VALUE"""),5.124612236E9) -> 5124612236 | I7: =IFERROR(__xludf.DUMMYFUNCTION("""COMPUTED_VALUE"""),"9AM-11AM") -> 9AM-11AM | J7: =IFERROR(__xludf.DUMMYFUNCTION("""COMPUTED_VALUE"""),0.0) -> 0 | K7: =IFERROR(__xludf.DUMMYFUNCTION("""COMPUTED_VALUE"""),"Complete") -> Complete | N7: =IFERROR(__xludf.DUMMYFUNCTION("""COMPUTED_VALUE"""),33.0) -> 33 | P7: =IFERROR(__xludf.DUMMYFUNCTION("""COMPUTED_VALUE"""),"Kit Delivery") -> Kit Delivery | T7: =IFERROR(__xludf.DUMMYFUNCTION("""COMPUTED_VALUE"""),46142.69212962963) -> 46142.692
